# auth.py
from fastapi import Depends, HTTPException, status
from fastapi.security import OAuth2PasswordBearer
from passlib.context import CryptContext
from jose import JWTError, jwt
from datetime import datetime, timedelta, timezone
from sqlalchemy.orm import Session
import models
from database import get_db # Import get_db instead of SessionLocal

# --- Configuration ---
SECRET_KEY = "YOUR_SUPER_SECRET_KEY_CHANGE_ME"
ALGORITHM = "HS256"
ACCESS_TOKEN_EXPIRE_MINUTES = 30

# --- Hashing ---
pwd_context = CryptContext(schemes=["bcrypt"], deprecated="auto")

def verify_password(plain_password, hashed_password):
    return pwd_context.verify(plain_password, hashed_password)

def get_password_hash(password):
    return pwd_context.hash(password)

# --- JWT Token ---
def create_access_token(data: dict, expires_delta: timedelta | None = None):
    to_encode = data.copy()
    if expires_delta:
        expire = datetime.now(timezone.utc) + expires_delta
    else:
        expire = datetime.now(timezone.utc) + timedelta(minutes=15)
    to_encode.update({"exp": expire})
    encoded_jwt = jwt.encode(to_encode, SECRET_KEY, algorithm=ALGORITHM)
    return encoded_jwt

# --- Authentication ---
oauth2_scheme = OAuth2PasswordBearer(tokenUrl="login")

def get_user(db: Session, user_id: str):
    return db.query(models.User).filter(models.User.user_id == user_id).first()

# This is the function that needed to be fixed.
def get_current_user(token: str = Depends(oauth2_scheme), db: Session = Depends(get_db)):
    credentials_exception = HTTPException(
        status_code=status.HTTP_401_UNAUTHORIZED,
        detail="Could not validate credentials",
        headers={"WWW-Authenticate": "Bearer"},
    )
    try:
        payload = jwt.decode(token, SECRET_KEY, algorithms=[ALGORITHM])
        user_id: str = payload.get("sub")
        if user_id is None:
            raise credentials_exception
    except JWTError:
        raise credentials_exception
    
    user = get_user(db, user_id=user_id)
    if user is None:
        raise credentials_exception
    return user